Workbook

Sheet Rekapitulasi
A1: Kode Kabupaten | B1: Keberadaan Usaha | E1: Jumlah | F1: Tindak Lanjut | G1: Persentase
B2: 0. Tidak Ditemukan | C2: 1. Ditemukan | D2: 2. Baru
A3: 7201 | B3: =COUNTIFS(Sheet1!C:C, 1, Sheet1!R:R, 0) | C3: =COUNTIFS(Sheet1!C:C, 1, Sheet1!R:R, 1) | D3: =COUNTIFS(Sheet1!C:C, 1, Sheet1!R:R, 2) | E3: =SUM(B3:D3) | F3: =COUNTIFS(Sheet1!C:C, 1, Sheet1!X:X, "<>") | G3: =IF(E3>0, (F3/E3)*100, 0)
A4: 7202 | B4: =COUNTIFS(Sheet1!C:C, 2, Sheet1!R:R, 0) | C4: =COUNTIFS(Sheet1!C:C, 2, Sheet1!R:R, 1) | D4: =COUNTIFS(Sheet1!C:C, 2, Sheet1!R:R, 2) | E4: =SUM(B4:D4) | F4: =COUNTIFS(Sheet1!C:C, 2, Sheet1!X:X, "<>") | G4: =IF(E4>0, (F4/E4)*100, 0)
A5: 7203 | B5: =COUNTIFS(Sheet1!C:C, 3, Sheet1!R:R, 0) | C5: =COUNTIFS(Sheet1!C:C, 3, Sheet1!R:R, 1) | D5: =COUNTIFS(Sheet1!C:C, 3, Sheet1!R:R, 2) | E5: =SUM(B5:D5) | F5: =COUNTIFS(Sheet1!C:C, 3, Sheet1!X:X, "<>") | G5: =IF(E5>0, (F5/E5)*100, 0)
A6: 7204 | B6: =COUNTIFS(Sheet1!C:C, 4, Sheet1!R:R, 0) | C6: =COUNTIFS(Sheet1!C:C, 4, Sheet1!R:R, 1) | D6: =COUNTIFS(Sheet1!C:C, 4, Sheet1!R:R, 2) | E6: =SUM(B6:D6) | F6: =COUNTIFS(Sheet1!C:C, 4, Sheet1!X:X, "<>") | G6: =IF(E6>0, (F6/E6)*100, 0)
A7: 7205 | B7: =COUNTIFS(Sheet1!C:C, 5, Sheet1!R:R, 0) | C7: =COUNTIFS(Sheet1!C:C, 5, Sheet1!R:R, 1) | D7: =COUNTIFS(Sheet1!C:C, 5, Sheet1!R:R, 2) | E7: =SUM(B7:D7) | F7: =COUNTIFS(Sheet1!C:C, 5, Sheet1!X:X, "<>") | G7: =IF(E7>0, (F7/E7)*100, 0)
A8: 7207 | B8: =COUNTIFS(Sheet1!C:C, 7, Sheet1!R:R, 0) | C8: =COUNTIFS(Sheet1!C:C, 7, Sheet1!R:R, 1) | D8: =COUNTIFS(Sheet1!C:C, 7, Sheet1!R:R, 2) | E8: =SUM(B8:D8) | F8: =COUNTIFS(Sheet1!C:C, 7, Sheet1!X:X, "<>") | G8: =IF(E8>0, (F8/E8)*100, 0)
A9: 7208 | B9: =COUNTIFS(Sheet1!C:C, 8, Sheet1!R:R, 0) | C9: =COUNTIFS(Sheet1!C:C, 8, Sheet1!R:R, 1) | D9: =COUNTIFS(Sheet1!C:C, 8, Sheet1!R:R, 2) | E9: =SUM(B9:D9) | F9: =COUNTIFS(Sheet1!C:C, 8, Sheet1!X:X, "<>") | G9: =IF(E9>0, (F9/E9)*100, 0)
A10: 7209 | B10: =COUNTIFS(Sheet1!C:C, 9, Sheet1!R:R, 0) | C10: =COUNTIFS(Sheet1!C:C, 9, Sheet1!R:R, 1) | D10: =COUNTIFS(Sheet1!C:C, 9, Sheet1!R:R, 2) | E10: =SUM(B10:D10) | F10: =COUNTIFS(Sheet1!C:C, 9, Sheet1!X:X, "<>") | G10: =IF(E10>0, (F10/E10)*100, 0)
A11: 7210 | B11: =COUNTIFS(Sheet1!C:C, 10, Sheet1!R:R, 0) | C11: =COUNTIFS(Sheet1!C:C, 10, Sheet1!R:R, 1) | D11: =COUNTIFS(Sheet1!C:C, 10, Sheet1!R:R, 2) | E11: =SUM(B11:D11) | F11: =COUNTIFS(Sheet1!C:C, 10, Sheet1!X:X, "<>") | G11: =IF(E11>0, (F11/E11)*100, 0)
A12: 7211 | B12: =COUNTIFS(Sheet1!C:C, 11, Sheet1!R:R, 0) | C12: =COUNTIFS(Sheet1!C:C, 11, Sheet1!R:R, 1) | D12: =COUNTIFS(Sheet1!C:C, 11, Sheet1!R:R, 2) | E12: =SUM(B12:D12) | F12: =COUNTIFS(Sheet1!C:C, 11, Sheet1!X:X, "<>") | G12: =IF(E12>0, (F12/E12)*100, 0)
A13: 7212 | B13: =COUNTIFS(Sheet1!C:C, 12, Sheet1!R:R, 0) | C13: =COUNTIFS(Sheet1!C:C, 12, Sheet1!R:R, 1) | D13: =COUNTIFS(Sheet1!C:C, 12, Sheet1!R:R, 2) | E13: =SUM(B13:D13) | F13: =COUNTIFS(Sheet1!C:C, 12, Sheet1!X:X, "<>") | G13: =IF(E13>0, (F13/E13)*100, 0)
A14: 7271 | B14: =COUNTIFS(Sheet1!C:C, 71, Sheet1!R:R, 0) | C14: =COUNTIFS(Sheet1!C:C, 71, Sheet1!R:R, 1) | D14: =COUNTIFS(Sheet1!C:C, 71, Sheet1!R:R, 2) | E14: =SUM(B14:D14) | F14: =COUNTIFS(Sheet1!C:C, 71, Sheet1!X:X, "<>") | G14: =IF(E14>0, (F14/E14)*100, 0)
A15: 7200 | B15: =SUM(B3:B14) | C15: =SUM(C3:C14) | D15: =SUM(D3:D14) | E15: =SUM(E3:E14) | F15: =SUM(F3:F14) | G15: =IF(E15>0, (F15/E15)*100, 0)

Sheet Sheet1
A1: assignment_id | B1: kdprov | C1: kdkab | D1: kdkec | E1: kddesa | F1: kdsls | G1: kdsubsls | H1: idsbr | I1: kode_kbli_prelist | J1: kbli_prelist | K1: kode_kbli | L1: kbli | M1: nama_usaha | N1: alamat_usaha | O1: nama_pengusaha | P1: nik_pengusaha | Q1: keberadaan_usaha | R1: keberadaan_usaha_value | S1: memiliki_izin_edar_bpom | T1: jumlah_varian_produk_terdaftar_bpom | U1: jumlah_varian_produk_tidak_terdaftar_bpom | V1: tindak_lanjut | W1: kbli_bpom_buped | X1: Hasil Tindak Lanjut | Y1: Alamat Sebenarnya | Z1: Unnamed: 25 | AA1: Keterangan | AB1: kode_identitas_16digit | AC1: status_by_id
A2: 88d4cb79-095f-403d-bb20-6ddbf031e2da | B2: 72 | C2: 1 | D2: 40 | E2: 14 | F2: 11 | G2: 0 | H2: 47125785 | I2: 10303 | J2: Pengeringan Buah-buahan dan Sayuran | M2: FARIDA SUADU | N2: DESA BAKA | Q2: 0. Tidak Ditemukan | R2: 0 | V2: Pastikan sesuai kondisi lapangan | W2: 0 | AB2: 7201040014001100 | AC2: APPROVED BY Pengawas
A3: 9993af48-7b82-4042-9895-cf6acac9a509 | B3: 72 | C3: 1 | D3: 40 | E3: 14 | F3: 14 | G3: 0 | H3: 48966033 | I3: 10792 | J3: Industri Kue Basah | M3: LINY YANI | N3: SALAKAN | Q3: 0. Tidak Ditemukan | R3: 0 | V3: Pastikan sesuai kondisi lapangan | W3: 0 | AB3: 7201040014001400 | AC3: APPROVED BY Pengawas
A4: 3041ec90-1b99-4050-ba9f-d44945406908 | B4: 72 | C4: 1 | D4: 41 | E4: 2 | F4: 2 | G4: 0 | H4: 43996271 | I4: 10779 | J4: Industri Bumbu Masakan Lainnya | M4: SANTI YABIE | N4: JL SAMUDRA | Q4: 0. Tidak Ditemukan | R4: 0 | V4: Pastikan sesuai kondisi lapangan | W4: 0 | AB4: 7201041002000200 | AC4: APPROVED BY Pengawas
A5: ebc25102-f999-427d-a096-d552361df474 | B5: 72 | C5: 1 | D5: 42 | E5: 5 | F5: 5 | G5: 0 | H5: 43620885 | I5: 10722 | J5: Industri Gula Merah | M5: HARSIN KASIANG | N5: DESA LALONG | Q5: 0. Tidak Ditemukan | R5: 0 | V5: Pastikan sesuai kondisi lapangan | W5: 0 | X5: prelist tidak berada di SLS seharusnya | Y5: Lalong, RT 1 Dusun 1 | AB5: 7201042005000500 | AC5: APPROVED BY Pengawas
A6: 0f40d5ef-174e-4f43-9a32-8d54902524b5 | B6: 72 | C6: 1 | D6: 51 | E6: 6 | F6: 6 | G6: 0 | H6: 43516347 | I6: 10710 | J6: Industri Produk Bakeri | K6: 1261 | L6: Pertanian Kelapa | M6: INDUSTRI KOPRA (RAIS YASIBANG) | N6: KOMPLEKS PAISUKUDANG, RT 6 DUSUN 3 ALAKASING - | O6: RAIS YASIBANG | Q6: 2. Baru | R6: 2 | V6: Pastikan kode KBLI sesuai dengan kode KBLI cakupan BPOM yang tertera dalam buku Pedoman | W6: 0 | AB6: 7201051006000600 | AC6: APPROVED BY Pengawas
A7: 1486cabf-72a5-4f9f-8058-29efa2a28157 | B7: 72 | C7: 1 | D7: 51 | E7: 6 | F7: 6 | G7: 0 | H7: 43516347 | I7: 10710 | J7: Industri Produk Bakeri | K7: 47112 | L7: Perdagangan Eceran Berbagai Macam Barang yang Utamanya Makanan, Minuman, atau Tembakau Selain dengan Sistem Swalayan | M7: PERDAGANGAN ECERAN SEMBAKO (MARIAH) | N7: KOMPLEKS PAISU KUDANG, RT 6 DUSUN 3 DESA ALAKASING - | O7: MARIAH RAH PANDAK | Q7: 2. Baru | R7: 2 | V7: Pastikan kode KBLI sesuai dengan kode KBLI cakupan BPOM yang tertera dalam buku Pedoman | W7: 1 | AB7: 7201051006000600 | AC7: APPROVED BY Pengawas
A8: 1486cabf-72a5-4f9f-8058-29efa2a28157 | B8: 72 | C8: 1 | D8: 51 | E8: 6 | F8: 6 | G8: 0 | H8: 43516347 | I8: 10710 | J8: Industri Produk Bakeri | K8: 47302 | L8: Perdagangan Eceran Bahan Bakar Selain di Sarana Pengisian Bahan Bakar | M8: USAHA BENSIN (MARIA RAH PANDAK) | N8: KOMPLEKS PAISU KUDANG, RT 6 DUSUN 3 DESA ALAKASING | O8: MARIAH RAH PANDAK | Q8: 2. Baru | R8: 2 | V8: Pastikan kode KBLI sesuai dengan kode KBLI cakupan BPOM yang tertera dalam buku Pedoman | W8: 0 | AB8: 7201051006000600 | AC8: APPROVED BY Pengawas
A9: 0f40d5ef-174e-4f43-9a32-8d54902524b5 | B9: 72 | C9: 1 | D9: 51 | E9: 6 | F9: 6 | G9: 0 | H9: 43516347 | I9: 10710 | J9: Industri Produk Bakeri | K9: 10750 | L9: Industri Makanan dan Masakan Olahan | M9: PEDAGANG SAYUR MASAK KELILING (HAENA) | N9: KOMPLEKS PAISUKUDANG, RT 6 DUSUN 3 ALAKASING - | O9: HAENA | Q9: 2. Baru | R9: 2 | S9: 3. Tidak | U9: 1 | W9: 1 | AB9: 7201051006000600 | AC9: APPROVED BY Pengawas
A10: e8beb5b3-d375-4a3f-b986-8e4bb7610387 | B10: 72 | C10: 1 | D10: 51 | E10: 6 | F10: 6 | G10: 0 | H10: 43516347 | I10: 10710 | J10: Industri Produk Bakeri | K10: 1261 | L10: Pertanian Kelapa | M10: PERTANIAN KELAPA (HADIR) | N10: KOMPLEKS PAISU KUDANG - | O10: HADIR | Q10: 2. Baru | R10: 2 | V10: Pastikan kode KBLI sesuai dengan kode KBLI cakupan BPOM yang tertera dalam buku Pedoman | W10: 0 | AB10: 7201051006000600 | AC10: SUBMITTED BY Pencacah
A11: 1589cc89-218e-4b39-87f1-7d6477aa2137 | B11: 72 | C11: 1 | D11: 51 | E11: 6 | F11: 6 | G11: 0 | H11: 43516347 | I11: 10710 | J11: Industri Produk Bakeri | K11: 1283 | L11: Pertanian Pala | M11: PERTANIAN PALA (IMRAN PANDAK) | N11: JLN TRANS PELING - | O11: IMRAN PANDAK | Q11: 2. Baru | R11: 2 | V11: Pastikan kode KBLI sesuai dengan kode KBLI cakupan BPOM yang tertera dalam buku Pedoman | W11: 0 | AB11: 7201051006000600 | AC11: APPROVED BY Pengawas
A12: f1fa4a91-b3a7-4916-98d2-afb8bad01925 | B12: 72 | C12: 1 | D12: 51 | E12: 6 | F12: 6 | G12: 0 | H12: 43516347 | I12: 10710 | J12: Industri Produk Bakeri | K12: 10421 | L12: Industri Kopra | M12: INDUSTRI KOPRA (DARSONO TAMBUAK) | N12: KOMPLEKS PAISUKUDANG, RT 6 DUSUN 3 DESA ALAKASING - | O12: DARSONO TAMBUAK | Q12: 2. Baru | R12: 2 | V12: Pastikan kode KBLI sesuai dengan kode KBLI cakupan BPOM yang tertera dalam buku Pedoman | W12: 1 | AB12: 7201051006000600 | AC12: APPROVED BY Pengawas
A13: 343314e3-b64d-449f-9314-078d50b2bad9 | B13: 72 | C13: 1 | D13: 51 | E13: 6 | F13: 6 | G13: 0 | H13: 43516347 | I13: 10710 | J13: Industri Produk Bakeri | K13: 10421 | L13: Industri Kopra | M13: INDUSTRI KOPRA (NAHRUN NUR PANGE) | N13: KOMPLEKS PAISU - | O13: NAHRUN NUR PANGE | Q13: 2. Baru | R13: 2 | V13: Pastikan kode KBLI sesuai dengan kode KBLI cakupan BPOM yang tertera dalam buku Pedoman | W13: 1 | AB13: 7201051006000600 | AC13: SUBMITTED BY Pencacah
A14: 6aee8c01-3d91-4820-ae76-c98123ec6acc | B14: 72 | C14: 1 | D14: 51 | E14: 6 | F14: 6 | G14: 0 | H14: 43516347 | I14: 10710 | J14: Industri Produk Bakeri | K14: 10421 | L14: Industri Kopra | M14: INDUSTRI KOPRA (IRSAN LAMASUI) | N14: JALAN TRANS PELING DESA ALAKASING | O14: IRSAN LAMASUI | Q14: 2. Baru | R14: 2 | V14: Pastikan kode KBLI sesuai dengan kode KBLI cakupan BPOM yang tertera dalam buku Pedoman | W14: 1 | AB14: 7201051006000600 | AC14: APPROVED BY Pengawas
A15: 17a2abfb-4d95-4e7a-adf7-95eaa537fdcc | B15: 72 | C15: 1 | D15: 51 | E15: 6 | F15: 6 | G15: 0 | H15: 43516347 | I15: 10710 | J15: Industri Produk Bakeri | K15: 10421 | L15: Industri Kopra | M15: INDUSTRI KOPRA (JASMAN TAUPO) | N15: PAISU KUDANG, RT 6 DUSUN 3 DESA ALAKASING - | O15: JASMAN TAUPO | Q15: 2. Baru | R15: 2 | V15: Pastikan kode KBLI sesuai dengan kode KBLI cakupan BPOM yang tertera dalam buku Pedoman | W15: 1 | AB15: 7201051006000600 | AC15: SUBMITTED BY Pencacah
A16: 88e10f32-f3d3-4d40-839b-167787757b4a | B16: 72 | C16: 1 | D16: 51 | E16: 6 | F16: 6 | G16: 0 | H16: 43516347 | I16: 10710 | J16: Industri Produk Bakeri | K16: 10421 | L16: Industri Kopra | M16: INDUSTRI KOPRA (ABDULAH SAMDENGE) | N16: KOMPLEKS PAISUKUDANG, RT 6 DUSUN 3 DESA ALAKASING. - | O16: ABDULAH SAMBADENGE | Q16: 2. Baru | R16: 2 | V16: Pastikan kode KBLI sesuai dengan kode KBLI cakupan BPOM yang tertera dalam buku Pedoman | W16: 1 | AB16: 7201051006000600 | AC16: APPROVED BY Pengawas
A17: 1782ddec-2d26-4100-9a58-8f0cdeec5eb2 | B17: 72 | C17: 1 | D17: 51 | E17: 6 | F17: 6 | G17: 0 | H17: 43516347 | I17: 10710 | J17: Industri Produk Bakeri | K17: 1261 | L17: Pertanian Kelapa | M17: PERTANIAN KELAPA (BAHMID A. MUTHALIB) | N17: KOMPLEKS PAISU KUDANG, RT6L 6 DUSUN 3 | O17: BAHMID A. MUTHALIB | Q17: 2. Baru | R17: 2 | V17: Pastikan kode KBLI sesuai dengan kode KBLI cakupan BPOM yang tertera dalam buku Pedoman | W17: 0 | AB17: 7201051006000600 | AC17: APPROVED BY Pengawas
A18: 1782ddec-2d26-4100-9a58-8f0cdeec5eb2 | B18: 72 | C18: 1 | D18: 51 | E18: 6 | F18: 6 | G18: 0 | H18: 43516347 | I18: 10710 | J18: Industri Produk Bakeri | K18: 90200 | L18: Aktivitas Seni Pertunjukan | M18: JASA HIBURAN (RABI'A A. BUKARIM) | N18: KOMPLEKS PAISU KUDANG, RT6L 6 DUSUN 3 | O18: RABI'A A. BUKARIM | Q18: 2. Baru | R18: 2 | V18: Pastikan kode KBLI sesuai dengan kode KBLI cakupan BPOM yang tertera dalam buku Pedoman | W18: 0 | AB18: 7201051006000600 | AC18: APPROVED BY Pengawas
A19: 17a2abfb-4d95-4e7a-adf7-95eaa537fdcc | B19: 72 | C19: 1 | D19: 51 | E19: 6 | F19: 6 | G19: 0 | H19: 43516347 | I19: 10710 | J19: Industri Produk Bakeri | K19: 1131 | L19: Pertanian Sayuran Daun | M19: PERTANIAN SAYURAN DAUN (HANIN YASIBANG) | N19: PAISU KUDANG, RT 6 DUSUN 3 DESA ALAKASING - | O19: HANIN YASIBANG | Q19: 2. Baru | R19: 2 | V19: Pastikan kode KBLI sesuai dengan kode KBLI cakupan BPOM yang tertera dalam buku Pedoman | W19: 0 | AB19: 7201051006000600 | AC19: SUBMITTED BY Pencacah
A20: f1fa4a91-b3a7-4916-98d2-afb8bad01925 | B20: 72 | C20: 1 | D20: 51 | E20: 6 | F20: 6 | G20: 0 | H20: 43516347 | I20: 10710 | J20: Industri Produk Bakeri | K20: 1283 | L20: Pertanian Pala | M20: PERTANIAN PALA (DARSONO TAMBUAK) | N20: KOMPLEKS PAISUKUDANG, RT 6 DUSUN 3 DESA ALAKASING - | O20: DARSONO TAMBUAK | Q20: 2. Baru | R20: 2 | V20: Pastikan kode KBLI sesuai dengan kode KBLI cakupan BPOM yang tertera dalam buku Pedoman | W20: 0 | AB20: 7201051006000600 | AC20: APPROVED BY Pengawas
A21: 343314e3-b64d-449f-9314-078d50b2bad9 | B21: 72 | C21: 1 | D21: 51 | E21: 6 | F21: 6 | G21: 0 | H21: 43516347 | I21: 10710 | J21: Industri Produk Bakeri | K21: 1261 | L21: Pertanian Kelapa | M21: PERTANIAN KELAPA (NAHRUN NUR PANGE) | N21: KOMPLEKS PAISU - | O21: NAHRUN NUR PANGE | Q21: 2. Baru | R21: 2 | V21: Pastikan kode KBLI sesuai dengan kode KBLI cakupan BPOM yang tertera dalam buku Pedoman | W21: 0 | AB21: 7201051006000600 | AC21: SUBMITTED BY Pencacah
... A35: 59d346e7-0b05-497a-8522-4ce1a2325b9b | B35: 72 | C35: 1 | D35: 51 | E35: 6 | F35: 6 | G35: 0 | H35: 43516347 | I35: 10710 | J35: Industri Produk Bakeri | K35: 10421 | L35: Industri Kopra | M35: INDUSTRI KOPRA (MURNI BELEK) | N35: JALAN TRANS PELING RT 6 DUSUN 3 DESA ALAKASING - | O35: MURNI BELEK | Q35: 2. Baru | R35: 2 | V35: Pastikan kode KBLI sesuai dengan kode KBLI cakupan BPOM yang tertera dalam buku Pedoman | W35: 1 | AB35: 7201051006000600 | AC35: APPROVED BY Pengawas
A36: e5959161-2da3-4b5b-89e0-fa43e59cd828 | B36: 72 | C36: 1 | D36: 51 | E36: 6 | F36: 6 | G36: 0 | H36: 43516347 | I36: 10710 | J36: Industri Produk Bakeri | K36: 95320 | L36: Reparasi dan Perawatan Sepeda Motor | M36: BENGKEL ATIS | N36: KOMPLEKS PAISU KUDANG | P36: 7207**********01 | Q36: 2. Baru | R36: 2 | V36: Pastikan kode KBLI sesuai dengan kode KBLI cakupan BPOM yang tertera dalam buku Pedoman | W36: 0 | AB36: 7201051006000600 | AC36: APPROVED BY Pengawas
A37: 36e22b44-4f3d-41ec-baf5-bf6e2dedf891 | B37: 72 | C37: 1 | D37: 51 | E37: 6 | F37: 6 | G37: 0 | H37: 43516347 | I37: 10710 | J37: Industri Produk Bakeri | K37: 10421 | L37: Industri Kopra | M37: INDUSTRI KOPRA (HUDIN S. SULULING) | N37: JALAN PAISU KUDANG RT 6 DUSUN 3 DESA ALAKASING - | O37: HUDIN S. SULULING | Q37: 2. Baru | R37: 2 | V37: Pastikan kode KBLI sesuai dengan kode KBLI cakupan BPOM yang tertera dalam buku Pedoman | W37: 1 | AB37: 7201051006000600 | AC37: SUBMITTED BY Pencacah
A38: 59d346e7-0b05-497a-8522-4ce1a2325b9b | B38: 72 | C38: 1 | D38: 51 | E38: 6 | F38: 6 | G38: 0 | H38: 43516347 | I38: 10710 | J38: Industri Produk Bakeri | K38: 1261 | L38: Pertanian Kelapa | M38: PERTANIAN KELAPA (MURNI BELEK) | N38: JALAN TRANS PELING RT 6 DUSUN 3 DESA ALAKASING - | O38: MURNI BELEK | Q38: 2. Baru | R38: 2 | V38: Pastikan kode KBLI sesuai dengan kode KBLI cakupan BPOM yang tertera dalam buku Pedoman | W38: 0 | AB38: 7201051006000600 | AC38: APPROVED BY Pengawas
A39: 7ee3acfe-5188-4287-8be9-c3a54c3076b7 | B39: 72 | C39: 1 | D39: 51 | E39: 6 | F39: 6 | G39: 0 | H39: 43516347 | I39: 10710 | J39: Industri Produk Bakeri | K39: 10421 | L39: Industri Kopra | M39: INDUSTRI KOPRA (ERWIN LALIO) | N39: KOMPLEKS PAISUKUDANG, RT 6 DUSUN 3 ALAKASING - | O39: ERWIN LALIO | Q39: 2. Baru | R39: 2 | V39: Pastikan kode KBLI sesuai dengan kode KBLI cakupan BPOM yang tertera dalam buku Pedoman | W39: 1 | AB39: 7201051006000600 | AC39: APPROVED BY Pengawas
A40: f1746b9c-e0eb-4d70-b45d-efc67718e2ba | B40: 72 | C40: 1 | D40: 51 | E40: 6 | F40: 6 | G40: 0 | H40: 43516347 | I40: 10710 | J40: Industri Produk Bakeri | M40: NASRIA M. DAPATI | N40: DESA ALAKASING | Q40: 0. Tidak Ditemukan | R40: 0 | V40: Pastikan sesuai kondisi lapangan | W40: 0 | AB40: 7201051006000600 | AC40: APPROVED BY Pengawas
A41: 1f860029-ee7f-4bb4-805e-8536ae6ff3bc | B41: 72 | C41: 1 | D41: 51 | E41: 6 | F41: 6 | G41: 0 | H41: 43516347 | I41: 10710 | J41: Industri Produk Bakeri | K41: 10421 | L41: Industri Kopra | M41: INDUSTRI KOPRA (AFRUDIN) | N41: KOMPLEKS PAISU KUDANG, RT 6 DUSUN 3 DESA ALAKASING - | O41: AFRUDDIN | Q41: 2. Baru | R41: 2 | V41: Pastikan kode KBLI sesuai dengan kode KBLI cakupan BPOM yang tertera dalam buku Pedoman | W41: 1 | AB41: 7201051006000600 | AC41: APPROVED BY Pengawas
A42: 8ff8bd3d-96a5-40ab-9eb1-471cc4503487 | B42: 72 | C42: 1 | D42: 51 | E42: 6 | F42: 6 | G42: 0 | H42: 43516347 | I42: 10710 | J42: Industri Produk Bakeri | K42: 10421 | L42: Industri Kopra | M42: INDUSTRI KOPRA (SALAM TAMBUAK) | N42: KOMPLEKS PAISU KUDANG RT 6 DUSUN 3, DESA ALAKASING | O42: SALAM TAMBUAK | Q42: 2. Baru | R42: 2 | V42: Pastikan kode KBLI sesuai dengan kode KBLI cakupan BPOM yang tertera dalam buku Pedoman | W42: 1 | AB42: 7201051006000600 | AC42: SUBMITTED BY Pencacah
A43: 156d67aa-2d27-47e9-8c00-ddf939ec5298 | B43: 72 | C43: 1 | D43: 51 | E43: 6 | F43: 6 | G43: 0 | H43: 43516347 | I43: 10710 | J43: Industri Produk Bakeri | K43: 1131 | L43: Pertanian Sayuran Daun | M43: PERTANIAN SAYURAN DAUN (ROSMAWATI) | N43: KOMPLEK PAISU KUDANG, RT 6 DUSUN 3 DESA ALAKASING - | O43: ROSMAWATI U. LAHANURU | Q43: 2. Baru | R43: 2 | V43: Pastikan kode KBLI sesuai dengan kode KBLI cakupan BPOM yang tertera dalam buku Pedoman | W43: 0 | AB43: 7201051006000600 | AC43: SUBMITTED BY Pencacah
A44: 8eb17a8e-10b2-4fb3-aea5-e79cea6b4d5e | B44: 72 | C44: 1 | D44: 51 | E44: 6 | F44: 6 | G44: 0 | H44: 43516347 | I44: 10710 | J44: Industri Produk Bakeri | K44: 23921 | L44: Industri Batu Bata dari Tanah Liat atau Keramik | M44: INDUSTRI BATU BATA (SAHRIN DADONG) | N44: KOMPLEKS PAISU KUDANG - | O44: SAHRIN DADONG | Q44: 2. Baru | R44: 2 | V44: Pastikan kode KBLI sesuai dengan kode KBLI cakupan BPOM yang tertera dalam buku Pedoman | W44: 0 | AB44: 7201051006000600 | AC44: SUBMITTED BY Pencacah
A45: 8ff8bd3d-96a5-40ab-9eb1-471cc4503487 | B45: 72 | C45: 1 | D45: 51 | E45: 6 | F45: 6 | G45: 0 | H45: 43516347 | I45: 10710 | J45: Industri Produk Bakeri | K45: 1131 | L45: Pertanian Sayuran Daun | M45: PERTANIAN SAYURAN DAUN (NINO SALABA) | N45: KOMPLEKS PAISU KUDANG RT 6 DUSUN 3, DESA ALAKASING | O45: NINO SALABA | Q45: 2. Baru | R45: 2 | V45: Pastikan kode KBLI sesuai dengan kode KBLI cakupan BPOM yang tertera dalam buku Pedoman | W45: 0 | AB45: 7201051006000600 | AC45: SUBMITTED BY Pencacah
A46: 12c1f3d1-fef7-4db0-a243-8bc7e196c885 | B46: 72 | C46: 1 | D46: 51 | E46: 6 | F46: 6 | G46: 0 | H46: 43516347 | I46: 10710 | J46: Industri Produk Bakeri | K46: 10421 | L46: Industri Kopra | M46: INDUSTRI KOPRA (ARIPUDIN A NDIBA) | N46: KOMPLEKS PAISUKUDANG, RT 6 DUSUN 3 - | O46: ARIPUDIN A. NDIBA | Q46: 2. Baru | R46: 2 | V46: Pastikan kode KBLI sesuai dengan kode KBLI cakupan BPOM yang tertera dalam buku Pedoman | W46: 1 | AB46: 7201051006000600 | AC46: APPROVED BY Pengawas
A47: 12c1f3d1-fef7-4db0-a243-8bc7e196c885 | B47: 72 | C47: 1 | D47: 51 | E47: 6 | F47: 6 | G47: 0 | H47: 43516347 | I47: 10710 | J47: Industri Produk Bakeri | K47: 1261 | L47: Pertanian Kelapa | M47: PERTANIAN KELAPA (ARIPUDIN A. NDIBA) | N47: KOMPLEKS PAISUKUDANG, RT 6 DUSUN 3 | O47: ARIPUDIN A. NDIBA | Q47: 2. Baru | R47: 2 | V47: Pastikan kode KBLI sesuai dengan kode KBLI cakupan BPOM yang tertera dalam buku Pedoman | W47: 0 | AB47: 7201051006000600 | AC47: APPROVED BY Pengawas
A48: 2d63cdf5-68eb-43e8-a6d7-2f218fefe4af | B48: 72 | C48: 1 | D48: 51 | E48: 6 | F48: 6 | G48: 0 | H48: 43516347 | I48: 10710 | J48: Industri Produk Bakeri | K48: 10421 | L48: Industri Kopra | M48: INDUSTRI KOPRA (NASIA) | N48: KOMPLEKS PAISU KUDANG, RT 6 DUSUN 3 DESA ALAKASING - | O48: NASIA | Q48: 2. Baru | R48: 2 | V48: Pastikan kode KBLI sesuai dengan kode KBLI cakupan BPOM yang tertera dalam buku Pedoman | W48: 1 | AB48: 7201051006000600 | AC48: APPROVED BY Pengawas
A49: a7a72995-12e2-4a57-8f11-8c02940e2734 | B49: 72 | C49: 1 | D49: 51 | E49: 6 | F49: 6 | G49: 0 | H49: 43516347 | I49: 10710 | J49: Industri Produk Bakeri | K49: 47742 | L49: Perdagangan Eceran Pakaian, Alas Kaki, dan Perlengkapan Pakaian Bekas | M49: PERDAGANGAN ECERAN PAKAIAN (FAJAR) | N49: KOMPLEKS PAISU KUDANG RT 6 DUSUN 3 DESA ALAKASING - | O49: FAJAR | Q49: 2. Baru | R49: 2 | V49: Pastikan kode KBLI sesuai dengan kode KBLI cakupan BPOM yang tertera dalam buku Pedoman | W49: 0 | AB49: 7201051006000600 | AC49: APPROVED BY Pengawas
A50: 5096590e-1207-4bb7-8cf3-b093bc31cd1f | B50: 72 | C50: 1 | D50: 51 | E50: 6 | F50: 6 | G50: 0 | H50: 43516347 | I50: 10710 | J50: Industri Produk Bakeri | K50: 10421 | L50: Industri Kopra | M50: INDUSTRI KOPRA (SAHRUDIN) | N50: JALAN PAISU KUDANG, RT 6 DUSUN 3 DESA ALAKASING - | O50: SAHRUDIN | Q50: 2. Baru | R50: 2 | V50: Pastikan kode KBLI sesuai dengan kode KBLI cakupan BPOM yang tertera dalam buku Pedoman | W50: 1 | AB50: 7201051006000600 | AC50: APPROVED BY Pengawas
A51: 8a0b811d-ac88-4a61-9321-dd674194a992 | B51: 72 | C51: 1 | D51: 51 | E51: 6 | F51: 6 | G51: 0 | H51: 43516347 | I51: 10710 | J51: Industri Produk Bakeri | K51: 20294 | L51: Industri Minyak Asiri Hulu | M51: INDUSTRI MINYAK NILAM ASIRI HULU (ISKANDAR A BUKARIM) | N51: KOMPLEKS PAISU KUDANG, RT 6 DUSUN 3 DESA ALAKASING - | O51: ISKANDAR A. BUKARIM | Q51: 2. Baru | R51: 2 | V51: Pastikan kode KBLI sesuai dengan kode KBLI cakupan BPOM yang tertera dalam buku Pedoman | W51: 1 | AB51: 7201051006000600 | AC51: APPROVED BY Pengawas
A52: b09f1af4-07b1-4173-bbcd-1fabfe71448f | B52: 72 | C52: 1 | D52: 51 | E52: 6 | F52: 6 | G52: 0 | H52: 43516347 | I52: 10710 | J52: Industri Produk Bakeri | K52: 1261 | L52: Pertanian Kelapa | M52: PERTANIAN KELAPA (SAMRIN PATAWE) | N52: KOMPLEKS PAISU KUDANG, RT 6 DUSUN 3 DESA ALAKASING | O52: SAMRIN PATAWE | Q52: 2. Baru | R52: 2 | V52: Pastikan kode KBLI sesuai dengan kode KBLI cakupan BPOM yang tertera dalam buku Pedoman | W52: 0 | AB52: 7201051006000600 | AC52: SUBMITTED BY Pencacah
... A59: 8a0b811d-ac88-4a61-9321-dd674194a992 | B59: 72 | C59: 1 | D59: 51 | E59: 6 | F59: 6 | G59: 0 | H59: 43516347 | I59: 10710 | J59: Industri Produk Bakeri | K59: 66199 | L59: Aktivitas Penunjang Jasa Keuangan Lainnya YTDL, Kecuali Asuransi dan Dana Pensiun | M59: USAHA BRILINK/ATM MINI (SITI JIJA LAMRIN MASKIRA) | N59: KOMPLEKS PAISU KUDANG, RT 6 DUSUN 3 DESA ALAKASING - | O59: SITI JIJA LAMRIN MASKIRA | Q59: 2. Baru | R59: 2 | V59: Pastikan kode KBLI sesuai dengan kode KBLI cakupan BPOM yang tertera dalam buku Pedoman | W59: 0 | AB59: 7201051006000600 | AC59: APPROVED BY Pengawas
...
